Workbook

Sheet UIO 2025
J2: INVENTARIO DE SERVIDORES VIRTUALIZADOS Y FISICOS UIO 2024
A5: Fecha de actualización:19/09/2025 | H5: Actualizado por: Evelyn Puetate
A7: CIUDAD | B7: ENCLOSURE | C7: SRV FISICOS | D7: SERIE | E7: IP DEL BLADE | F7: TOTAL SRV FISICOS | G7: CARACTERISTICAS | H7: SOPORTE | I7: # SRV VIRTUALES | J7: TIPO DE SERVIDOR | K7: SRV VIRTUALES | L7: APLICACIÓN | M7: IP INTERNA | N7: IP PUBLICA | O7: PROTECCIÓN DE TREND MCRO XDR - SRV | P7: CORTEX | Q7: Persona responsable del uso del SRV | R7: PANDORA | S7: SISTEMA OPERATIVO | T7: MEMORIA | U7: Espacio Disco | V7: Procesador | W7: SISTEMAS CRITICOS | X7: SERVIDOR PRODUCCIÓN / PREPRODUCCIÓN | Y7: BASE DE DATOS | Z7: VERSIÓN DB | AA7: COSTO SOPORTE | AB7: EMPRESA QUE DA SOPORTE | AC7: BACKUP SE REALIZA | AD7: PLATAFORMA DE BACKUP | AE7: POLITICA DE BACKUP
A8: UIO - SIMPLIVITY | B8: tvc-srv-esx1 | C8: ProLiant DL380 2 x Intel(R) Xeon(R) Gold 6230 CPU @ 2.10GHz x 20 Cores | D8: 2M211600MH | E8: 192.168.34.160 | F8: 4 | G8: Gen 10 1.5 TB RAM | H8: SI | I8: =COUNTIF(J9:J97,"=VIRTUAL") -> 89 | J8: VIRTUAL | K8: Fortiweb | L8: Firewall Waf | M8: 192.168.33.50 | N8: 200.63.213.18 | O8: - | P8: - | Q8: Luis Conteron / Guillermo Jurado | R8: NO | S8: Other 2.6.x Linux (64-bit) | T8: 8 | U8: 150 | V8: 8 | W8: ALTO | X8: PRODUCCIÓN | Y8: NA | Z8: NA | AC8: SI | AD8: Veritas | AE8: Veritas-FUllTue-Ret15_UIO_04
B9: tvc-srv-esx2 | C9: ProLiant DL381 2 x Intel(R) Xeon(R) Gold 6230 CPU @ 2.10GHz x 20 Cores | D9: 2M211600MG | E9: 192.168.34.162 | G9: Gen 10 1.5 TB RAM | H9: SI | J9: VIRTUAL | K9: OmniStackVC-192-168-34-161 | L9: Servidor propio de trabajo SimpliVity | M9: 192.168.34.161 | O9: NO | P9: NO | Q9: Evelyn Puetate | R9: SI | S9: Ubuntu Linux (64-bit) | T9: 92 | U9: 209.96 | V9: 8 | W9: BAJO | X9: PRODUCCIÓN | Y9: NA | Z9: NA | AC9: NO es parte sistema operativo de Simplivity | AD9: - | AE9: NO es parte sistema operativo de Simplivity
B10: tvc-srv-esx3 | C10: ProLiant DL380 2 x Intel(R) Xeon(R) Gold 6238 CPU @ 2.10GHz x 22 Cores | D10: 2M232601ZG | E10: 192.168.34.164 | G10: Gen 10 1 TB RAM | H10: SI | J10: VIRTUAL | K10: OmniStackVC-192-168-34-163 | L10: Servidor propio de trabajo SimpliVity | M10: 192.168.34.163 | O10: NO | P10: NO | Q10: Evelyn Puetate | R10: SI | S10: Ubuntu Linux (64-bit) | T10: 92 | U10: 209.96 | V10: 8 | W10: BAJO | X10: PRODUCCIÓN | Y10: NA | Z10: NA | AC10: NO es parte sistema operativo de Simplivity | AD10: - | AE10: NO es parte sistema operativo de Simplivity
B11: tvc-srv-esx4 | C11: ProLiant DL380 2 x Intel(R) Xeon(R) Gold 6238 CPU @ 2.10GHz x 22 Cores | D11: 2M232601ZH | E11: 192.168.34.166 | G11: Gen 10 1 TB RAM | H11: SI | J11: VIRTUAL | K11: OmniStackVC-192-168-34-165 | L11: Servidor propio de trabajo SimpliVity | M11: 192.168.34.165 | O11: NO | P11: NO | Q11: Evelyn Puetate | R11: SI | S11: Ubuntu Linux (64-bit) | T11: 92 | U11: 209.96 | V11: 8 | W11: BAJO | X11: PRODUCCIÓN | Y11: NA | Z11: NA | AC11: NO es parte sistema operativo de Simplivity | AD11: - | AE11: NO es parte sistema operativo de Simplivity
J12: VIRTUAL | K12: OmniStackVC-192-168-34-167 | L12: Servidor propio de trabajo SimpliVity | M12: 192.168.34.167 | O12: NO | P12: NO | Q12: Evelyn Puetate | R12: SI | S12: Ubuntu Linux (64-bit) | T12: 92 | U12: 209.96 | V12: 8 | W12: BAJO | X12: PRODUCCIÓN | Y12: NA | Z12: NA | AC12: NO es parte sistema operativo de Simplivity | AD12: - | AE12: NO es parte sistema operativo de Simplivity
J13: VIRTUAL | K13: tvc-srv-adprint | L13: Administrador de impresoras UIO | M13: 192.168.21.17 | O13: SI | P13: - | Q13: Hector Miranda/Graciela Ortiz | R13: SI | S13: Microsoft Windows Server 2016 (64-bit) | T13: 16 | U13: 350 | V13: 4 | W13: MEDIO | X13: PRODUCCIÓN | Y13: NA | Z13: NA | AC13: SI | AD13: Veritas | AE13: Veritas-FUllWed-Ret15_UIO_08
J14: VIRTUAL | K14: tvc-srv-aduio2 | L14: Conector del AD | M14: 192.168.21.26 | N14: 200.63.213.27 | O14: SI | P14: - | Q14: Evelyn Puetate | R14: SI | S14: Microsoft Windows Server 2016 (64-bit) | T14: 20 | U14: 150 | V14: 4 | W14: ALTO | X14: PRODUCCIÓN | Y14: NA | Z14: NA | AC14: SI | AD14: Veritas | AE14: Veritas-FUllWed-Ret15_UIO_08
J15: VIRTUAL | K15: tvc-srv-aduio3 | L15: Active Directory secundario | M15: 192.168.21.27 | O15: SI | P15: - | Q15: Evelyn Puetate | R15: SI | S15: Microsoft Windows Server 2016 (64-bit) | T15: 20 | U15: 150 | V15: 4 | W15: ALTO | X15: PRODUCCIÓN | AC15: SI | AD15: Veritas | AE15: Veritas-FUllWed-Ret15_UIO_08
J16: VIRTUAL | K16: tvc-srv-agdi | L16: Pagina Web Agencia Digital, tmbn tiene xtrim.tv, xtrim.com.ec, Pagina de Ingreso de contrato para vendedores, proveedores y distribuidores - mixtrim.com.ec/IngresoContratos | M16: 192.168.21.243 | N16: 200.63.213.43 | O16: SI | P16: - | Q16: Hector Miranda /Administrador de aplicaciones | R16: SI | S16: Red Hat Enterprise Linux 7 (64-bit) | T16: 48 | U16: 180 | V16: 8 | W16: ALTO | X16: PRODUCCIÓN | Y16: MySQL | Z16: 5.6.28 Community Edition 64 bits | AC16: SI | AD16: Veritas | AE16: Veritas-FUllMon-Ret15_UIO_02
J17: VIRTUAL | K17: tvc-srv-amas | L17: Servidor de amas - Relacionado con las llamadas telefonicas. | M17: 192.168.21.31 | O17: SI | P17: - | Q17: Hector Miranda /Administrador de aplicaciones | R17: SI | S17: Windows 10 | T17: 8 | U17: 931.65 | V17: 4 | W17: BAJO | X17: PRODUCCIÓN | AC17: SI | AD17: Veritas | AE17: Veritas-FUllMon-Ret15_UIO_02
J18: VIRTUAL | K18: tvc-srv-apjaira | L18: Mesa de Servicios - Flujos internos. (con el tiempo se dará de baja) | M18: 192.168.21.35 | O18: SI | P18: - | Q18: Hector Miranda /Administrador de aplicaciones | R18: SI | S18: Microsoft Windows Server 2016 (64-bit) | T18: 20 | U18: 400 | V18: 4 | W18: BAJO | X18: PRODUCCIÓN | Y18: NA | Z18: NA | AC18: SI | AD18: Veritas | AE18: Veritas-FUllThu-Ret15_UIO_09
J19: VIRTUAL | K19: tvc-srv-appadm | L19: Aplicaciones del sistema de nomina - Datalife | M19: 192.168.21.101 | O19: - | P19: SI | Q19: Jaqueline Andrade/Carlos Ayala/Christian Castillo | R19: SI | S19: Microsoft Windows Server 2022 (64-bit) | T19: 16 | U19: 160 | V19: 2 | W19: ALTO | X19: PRODUCCIÓN | AC19: SI | AD19: Veritas | AE19: Veritas-FUllWed-Ret15_UIO_06
J20: VIRTUAL | K20: tvc-srv-as2back - ELIMINADO | L20: SERVIDOR DE RESPALDO DEL AS2, DE LA INFOPRMACIÓN QUE ESTA EN EL ONEDRIVE. (3ER RESPALDO) | M20: 192.168.21.15 | O20: - | P20: SI | Q20: Jose Fernandez/Ivone Intriago | R20: SI | S20: Microsoft Windows Server 2022 (64-bit) | T20: 4 | U20: 300 | V20: 4 | W20: ALTO | X20: PRODUCCIÓN | AC20: SI | AD20: Veritas | AE20: Veritas-FUllMon-Ret15_UIO_00 Veritas-FullFri-Ret15_UIO_14
J21: VIRTUAL | K21: tvc-srv-autosrv | L21: Servidor autoservicios | M21: 192.168.21.16 | O21: - | P21: SI | Q21: Hector Miranda /Administrador de aplicaciones | R21: SI | S21: Ubuntu 22,04 LTS Linux (64-bit) | T21: 8 | U21: 100 | V21: 4 | W21: ALTO | X21: PRODUCCIÓN | Y21: NA | Z21: NA | AC21: SI | AD21: Veritas | AE21: Veritas-FUllTue-Ret15_UIO_05
J22: VIRTUAL | K22: tvc-srv-autosrvclon | M22: 192.168.21.20 | O22: - | P22: SI | Q22: Hector Miranda /Administrador de aplicaciones | R22: SI | S22: Ubuntu 22,04 LTS Linux (64-bit) | T22: 8 | U22: 100 | V22: 4 | W22: ALTO | X22: PRODUCCIÓN | Y22: NA | Z22: NA
J23: VIRTUAL | K23: tvc-srv-bdadm | L23: Base de datos de sistema de nomina | M23: 192.168.21.102 | O23: - | P23: SI | Q23: Jaqueline Andrade/Carlos Ayala/James Pesantes | R23: SI | S23: Microsoft Windows Server 2022 (64-bit) | T23: 16 | U23: 500 | V23: 4 | W23: ALTO | X23: PRODUCCIÓN | AC23: SI | AD23: veritas | AE23: Veritas-FUllWed-Ret15_UIO_06
J24: VIRTUAL | K24: xtr-srv-ansible-platform-gateway | L24: Ansible Plataform Gateway | M24: 192.168.21.6 | O24: - | P24: SI | Q24: Evelyn Puetate | R24: SI | S24: Red Hat Enterprise Linux 9 (64-bit) | T24: 16 | U24: 60 | V24: 4 | W24: MEDIO | X24: PRODUCCIÓN | AC24: SI | AD24: veritas | AE24: Veritas-FUllTue-Ret15_UIO_06
J25: VIRTUAL | K25: xtr-srv-ansible-automation-hub | L25: Ansible Private Automation Hub | M25: 192.168.21.7 | O25: - | P25: SI | Q25: Evelyn Puetate | R25: SI | S25: Red Hat Enterprise Linux 9 (64-bit) | T25: 16 | U25: 60 | V25: 4 | W25: MEDIO | X25: PRODUCCIÓN | AC25: SI | AD25: veritas | AE25: Veritas-FUllTue-Ret15_UIO_05
J26: VIRTUAL | K26: xtr-srv-ansible-controller-control | L26: Ansible Automation Controller | M26: 192.168.21.12 | O26: - | P26: SI | Q26: Evelyn Puetate | R26: SI | S26: Red Hat Enterprise Linux 9 (64-bit) | T26: 16 | U26: 180 | V26: 4 | W26: MEDIO | X26: PRODUCCIÓN | AC26: SI | AD26: veritas | AE26: Veritas-FUllTue-Ret15_UIO_04
J27: VIRTUAL | K27: xtr-srv-ansible-controller-execution | L27: Ansible Controller Excecution | M27: 192.168.21.28 | O27: - | P27: SI | Q27: Evelyn Puetate | R27: SI | S27: Red Hat Enterprise Linux 9 (64-bit) | T27: 16 | U27: 60 | V27: 4 | W27: MEDIO | X27: PRODUCCIÓN | AC27: SI | AD27: veritas | AE27: Veritas-FUllMon-Ret15_UIO_02
J28: VIRTUAL | K28: tvc-srv-ansible-pivot | L28: Ansible Pivot | M28: 192.168.21.4 | O28: - | P28: SI | Q28: Evelyn Puetate | R28: SI | S28: Microsoft Windows Server 2022 (64-bit) | T28: 8 | U28: 90 | V28: 4 | W28: MEDIO | X28: PRODUCCIÓN
J29: VIRTUAL | K29: tvc-srv-backupAS2 | L29: Backup AS2 | M29: 192.168.21.34 | P29: SI | Q29: Evelyn Puetate | R29: SI | S29: Microsoft Windows Server 2022 (64-bit) | T29: 16 | U29: 1240 | V29: 8 | W29: ALTO | X29: PRODUCCIÓN | AC29: SI | AD29: Veritas
J30: VIRTUAL | K30: tvc-srv-cluster3 | L30: Cluster base de datos | M30: 192.168.21.25 | O30: - | P30: SI | Q30: Carlos Ayala / James Pesantes | R30: SI | S30: Red Hat Enterprise Linux 9 (64-bit) | T30: 4 | U30: 400 | V30: 2 | W30: ALTO | X30: PRODUCCIÓN | Y30: NA | Z30: NA | AC30: SI | AD30: Veritas | AE30: Veritas-FUllTue-Ret15_UIO_05
J31: VIRTUAL | K31: tvc-srv-colecsoc | L31: Logs del SOC | M31: 192.168.21.236 | O31: - | P31: SI | Q31: Jose Fernandez/Alejandro Alvarez | R31: SI | S31: Red Hat Enterprise Linux 9.2 (64-bit) | T31: 8 | U31: 250 | V31: 4 | W31: ALTO | X31: PRODUCCIÓN | AC31: SI | AD31: Veritas | AE31: Veritas-FUllMon-Ret15_UIO_01
J32: VIRTUAL | K32: tvc-srv-condell | L32: Servidor Thincliente Dell | M32: 192.168.21.5 | O32: - | P32: SI | Q32: Evelyn Puetate | R32: SI | S32: Microsoft Windows Server 2019 (64-bit) | T32: 8 | U32: 100 | V32: 4 | W32: ALTO | X32: PRODUCCIÓN | Y32: NA | Z32: NA | AC32: SI | AD32: Veritas | AE32: Veritas-FullWed-Ret15_UIO_07
J33: VIRTUAL | K33: tvc-srv-dbas2bi | L33: Enviar informacion de base de datos AS2 | M33: 192.168.21.13 | N33: 200.63.213.82 | O33: - | P33: SI | Q33: Carlos Ayala/Christian Castillo | R33: SI | S33: Red Hat Enterprise Linux 9 (64-bit) | T33: 8 | U33: 300 | V33: 8 | W33: ALTO | X33: PRODUCCIÓN | AC33: SI | AD33: veaam | AE33: Veeam-FullWed-Ret15_UIO_23
J34: VIRTUAL | K34: tvc-srv-dbjaira | L34: Servidor base de datos Jira | M34: 192.168.21.36 | O34: SI | P34: - | Q34: Carlos Ayala/Christian Castillo | R34: SI | S34: Microsoft Windows Server 2012 (64-bit) | T34: 8 | U34: 550 | V34: 2 | W34: MEDIO | X34: PRODUCCIÓN | Y34: SQL SERVER | Z34: SQL Server 2012 | AC34: SI | AD34: Veritas | AE34: Veritas-FUllThu-Ret15_UIO_09
J35: VIRTUAL | K35: tvc-srv-desa-www | L35: Servidor www FSM | M35: 192.168.21.197 | O35: SI | P35: - | Q35: Hector Miranda/Administrador de aplicaciones | R35: SI | S35: Red Hat Enterprise Linux 6 (64-bit) | T35: 38 | U35: 100 | V35: 10 | W35: ALTO | X35: DESARROLLO | AC35: SI | AE35: Veritas-FUllTue-Ret15_UIO_04
J36: VIRTUAL | K36: tvc-srv-dhcpuio | L36: Servidor DHCP y consola de Unifi (Wifi) | M36: 192.168.21.2 | O36: SI | P36: - | Q36: Luis Conteron/Guillermo Jurado | R36: SI | S36: Microsoft Windows Server 2016 (64-bit) | T36: 8 | U36: 80 | V36: 4 | W36: ALTO | X36: PRODUCCIÓN | Y36: NA | Z36: NA | AC36: SI | AD36: Veritas | AE36: Veritas-FUllWed-Ret15_UIO_08
J37: VIRTUAL | K37: tvc-srv-exuio | L37: Servidor de Correo | M37: 192.168.21.50 192.168.21.196 | N37: 200.63.213.13 | O37: - | P37: SI | Q37: Evelyn Puetate | R37: SI | S37: Microsoft Windows Server 2022 (64-bit) | T37: 20 | U37: =250+150 -> 400 | V37: 4 | W37: ALTO | X37: PRODUCCIÓN | Y37: NA | Z37: NA | AC37: SI | AD37: Veritas | AE37: Veritas-FUllWed-Ret15_UIO_06
J38: VIRTUAL | K38: tvc-srv-finform | L38: Servidor de Formas Hiperk - Reemplazado por el AS2 | M38: 192.168.21.46 | O38: SI | P38: - | Q38: Hector Miranda/Administrador de aplicaciones | R38: SI | S38: Microsoft Windows Server 2016 (64-bit) | T38: 6 | U38: 250 | V38: 4 | W38: BAJO | X38: PREPRODUCCIÓN | Y38: NA | Z38: NA | AC38: SI | AD38: Veritas | AE38: Veritas-FUllWed-Ret15_UIO_06
J39: VIRTUAL | K39: tvc-srv-fsm | L39: Base Datos FSM | M39: 192.168.21.124 | O39: SI | P39: - | Q39: Carlos Ayala/James Pesantes | R39: SI | S39: Red Hat Enterprise Linux 6.4 (64-bit) | T39: 64 | U39: 3000 | V39: 8 | W39: ALTO | X39: PRODUCCIÓN | Y39: ORACLE | Z39: Oracle 11g R2 | AC39: Se respalda Base de Datos | AD39: Veritas | AE39: Veritas-FUllTue-Ret15_UIO_04
J40: VIRTUAL | K40: tvc-srv-ftp | L40: FTP Recargas efectos de consiliaciones | M40: 192.168.21.157 | N40: 200.63.213.64 | O40: SI | P40: - | Q40: Hector Miranda/Administrador de aplicaciones | R40: SI | S40: Red Hat Enterprise Linux 6 (64-bit) | T40: 2 | U40: 60 | V40: 1 | W40: ALTO | X40: PRODUCCIÓN | Y40: NA | Z40: NA | AC40: SI | AD40: Veritas | AE40: Veritas-FUllTue-Ret15_UIO_03
J41: VIRTUAL | K41: tvc-srv-ftpac | L41: Ftp actualizaciones BackOffice | M41: 192.168.21.203 | N41: 200.63.213.68 | O41: SI | P41: - | Q41: pendiente de confirmacion David Villamar | R41: SI | S41: Red Hat Enterprise Linux 6 (64-bit) | T41: 4 | U41: 50 | V41: 2 | W41: MEDIO | X41: PRODUCCIÓN | Y41: NA | Z41: NA | AC41: SI | AD41: veeam | AE41: Veritas-FullFri-Ret15_UIO_12
J42: VIRTUAL | K42: tvc-srv-gruptvc | L42: Pruebas pagina Grupo TVCable | M42: 192.168.21.123/192.168.122.1 | O42: SI | P42: - | Q42: Carlos Ayala / David Villamar | R42: SI | S42: Red Hat Enterprise Linux 7 (64-bit) | T42: 4 | U42: 120 | V42: 2 | W42: BAJO | X42: PREPRODUCCIÓN | Y42: MySQL | Z42: 5.6.28 Community Edition 64 bits | AC42: SI | AD42: Veritas | AE42: Veritas-FUllMon-Ret15_UIO_01
J43: VIRTUAL | K43: tvc-srv-guardium | L43: Servidor firewall base de datos | M43: 192.168.21.210 | N43: 200.63.213.56 | O43: SI | P43: - | Q43: Carlos Ayala/James Pesantes | R43: SI | S43: Red Hat Enterprise Linux 7 (64-bit) | T43: 32 | U43: 1000 | V43: 8 | W43: ALTO | X43: PRODUCCIÓN | Y43: MYSQL | Z43: MySQL modificado | AC43: SI | AD43: Veritas | AE43: Veritas-FUllTue-Ret15_UIO_04
J44: VIRTUAL | K44: tvc-srv-jenkins | L44: Servidor jenkins para bitbucket | M44: 192.168.21.14 | N44: 200.63.213.65 | O44: - | P44: SI | Q44: Mauricio Rodriguez | R44: SI | S44: Ubuntu Linux (64-bit) | T44: 6 | U44: 60 | V44: 2 | W44: MEDIO | X44: PRODUCCIÓN | Y44: NA | Z44: NA | AC44: SI | AD44: Veritas | AE44: Veritas-FUllTue-Ret15_UIO_03
...

Sheet UIO
J2: INVENTARIO DE SERVIDORES VIRTUALIZADOS Y FISICOS UIO 2024
A5: Fecha de actualización: 4Julio2024 | H5: Actualizado por: Evelyn Puetate
A7: CIUDAD | B7: ENCLOSURE | C7: SRV FISICOS | D7: SERIE | E7: IP DEL BLADE | F7: TOTAL SRV FISICOS | G7: CARACTERISTICAS | H7: SOPORTE | I7: # SRV VIRTUALES | J7: TIPO DE SERVIDOR | K7: SRV VIRTUALES | L7: APLICACIÓN | M7: IP INTERNA | N7: IP PUBLICA | O7: PROTECCIÓN DE TREND MCRO XDR - SRV | P7: CORTEX | Q7: Persona responsable del uso del SRV | R7: SISTEMA OPERATIVO | S7: MEMORIA | T7: Espacio Disco | U7: Procesador | V7: SISTEMAS CRITICOS | W7: SERVIDOR PRODUCCIÓN / PREPRODUCCIÓN | X7: BASE DE DATOS | Y7: VERSIÓN DB | Z7: COSTO SOPORTE | AA7: EMPRESA QUE DA SOPORTE | AB7: BACKUP SE REALIZA | AC7: PLATAFORMA DE BACKUP | AD7: POLITICA DE BACKUP
A8: UIO | B8: tvc-srv-esx1 | C8: ProLiant DL380 2 x Intel(R) Xeon(R) Gold 6230 CPU @ 2.10GHz x 20 Cores | D8: 2M211600MH | E8: shp | F8: 4 | G8: Gen 10 1.5 TB RAM | H8: SI | I8: =COUNTIF(J8:J106,"=VIRTUAL") -> 99 | J8: VIRTUAL | K8: Fortiweb | L8: Firewall Waf | M8: 192.168.21.32 | N8: 200.63.213.18 | O8: - | P8: - | Q8: Luis Conteron / Guillermo Jurado | R8: Other 2.6.x Linux (64-bit) | S8: 8 | T8: 150 | U8: 8 | V8: ALTO | W8: PRODUCCIÓN | X8: NA | Y8: NA | AB8: SI | AC8: Veritas | AD8: Veritas-FUllTue-Ret15_UIO_04
A9: UIO | B9: tvc-srv-esx2 | C9: ProLiant DL381 2 x Intel(R) Xeon(R) Gold 6230 CPU @ 2.10GHz x 20 Cores | D9: 2M211600MG | E9: 192.168.34.162 | G9: Gen 10 1.5 TB RAM | H9: SI | J9: VIRTUAL | K9: OmniStackVC-192-168-34-161 | L9: Servidor propio de trabajo SimpliVity | M9: 192.168.34.161 | O9: - | P9: - | Q9: Evelyn Puetate | R9: Ubuntu Linux (64-bit) | S9: 92 | T9: 209.96 | U9: 8 | V9: BAJO | W9: PRODUCCIÓN | X9: NA | Y9: NA | AB9: NO es parte sistema operativo de Simplivity | AC9: -
A10: UIO | B10: tvc-srv-esx3 | C10: ProLiant DL380 2 x Intel(R) Xeon(R) Gold 6238 CPU @ 2.10GHz x 22 Cores | D10: 2M232601ZG | E10: 192.168.34.164 | G10: Gen 10 1 TB RAM | H10: SI | J10: VIRTUAL | K10: OmniStackVC-192-168-34-163 | L10: Servidor propio de trabajo SimpliVity | M10: 192.168.34.163 | O10: - | P10: - | Q10: Evelyn Puetate | R10: Ubuntu Linux (64-bit) | S10: 92 | T10: 209.96 | U10: 8 | V10: BAJO | W10: PRODUCCIÓN | X10: NA | Y10: NA | AB10: NO es parte sistema operativo de Simplivity | AC10: -
A11: UIO | B11: tvc-srv-esx4 | C11: ProLiant DL380 2 x Intel(R) Xeon(R) Gold 6238 CPU @ 2.10GHz x 22 Cores | D11: 2M232601ZH | E11: 192.168.34.166 | G11: Gen 10 1 TB RAM | H11: SI | J11: VIRTUAL | K11: OmniStackVC-192-168-34-165 | L11: Servidor propio de trabajo SimpliVity | M11: 192.168.34.165 | O11: - | P11: - | Q11: Evelyn Puetate | R11: Ubuntu Linux (64-bit) | S11: 92 | T11: 209.96 | U11: 8 | V11: BAJO | W11: PRODUCCIÓN | X11: NA | Y11: NA | AB11: NO es parte sistema operativo de Simplivity | AC11: -
J12: VIRTUAL | K12: OmniStackVC-192-168-34-167 | L12: Servidor propio de trabajo SimpliVity | M12: 192.168.34.167 | O12: - | P12: - | Q12: Evelyn Puetate | R12: Ubuntu Linux (64-bit) | S12: 92 | T12: 209.96 | U12: 8 | V12: BAJO | W12: PRODUCCIÓN | X12: NA | Y12: NA | AB12: NO es parte sistema operativo de Simplivity | AC12: -
J13: VIRTUAL | K13: tvc-bss-crm-02 | L13: Alepo- CRM + Billing + Product catalogue + Inventory + Trouble Ticketing + Affiliate Management + Off line rating | M13: 192.168.21.60 | O13: - | P13: SI | Q13: Pendiente de confirmacion Xavier Leon | R13: Oracle Linux 8 (64-bit) | S13: 48 | T13: 800 | U13: 32 | V13: ALTO | W13: PRODUCCIÓN | X13: NA | Y13: NA | AB13: SI | AC13: Veritas | AD13: Veritas-FUllMon-Ret15_UIO_00
J14: VIRTUAL | K14: tvc-bss-ffm-02 | L14: Alepo - FFM | M14: 192.168.21.61 | O14: - | P14: SI | Q14: Pendiente de confirmacion Xavier Leon | R14: Oracle Linux 8 (64-bit) | S14: 32 | T14: 500 | U14: 8 | V14: ALTO | W14: PRODUCCIÓN | X14: NA | Y14: NA | AB14: SI | AC14: Veritas | AD14: Veritas-FUllMon-Ret15_UIO_00
J15: VIRTUAL | K15: tvc-bss-inter-02 | L15: Alepo - Interconnect | M15: 192.168.21.65 | O15: - | P15: SI | Q15: Pendiente de confirmacion Xavier Leon | R15: Oracle Linux 8 (64-bit) | S15: 48 | T15: 3430 | U15: 32 | V15: ALTO | W15: PRODUCCIÓN | X15: NA | Y15: NA | AB15: SI | AC15: Veritas | AD15: Veritas-FUllMon-Ret15_UIO_00
J16: VIRTUAL | K16: tvc-bss-mediation-02 | L16: Alepo - Mediation | M16: 192.168.21.64 | O16: - | P16: SI | Q16: Pendiente de confirmacion Xavier Leon | R16: Oracle Linux 8 (64-bit) | S16: 32 | T16: 600 | U16: 16 | V16: ALTO | W16: PRODUCCIÓN | X16: NA | Y16: NA | AB16: SI | AC16: Veritas | AD16: Veritas-FUllMon-Ret15_UIO_00
J17: VIRTUAL | K17: tvc-bss-oms-02 | L17: Alepo - Order Management | M17: 192.168.21.66 | O17: - | P17: SI | Q17: Pendiente de confirmacion Xavier Leon | R17: Oracle Linux 8 (64-bit) | S17: 32 | T17: 300 | U17: 16 | V17: ALTO | W17: PRODUCCIÓN | X17: NA | Y17: NA | AB17: SI | AC17: Veritas | AD17: Veritas-FUllMon-Ret15_UIO_00
J18: VIRTUAL | K18: tvc-bss-wsrc-02 | L18: Alepo - Web Self Care + Chatbot + Whatsapp | M18: 192.168.21.62 | O18: - | P18: SI | Q18: Pendiente de confirmacion Xavier Leon | R18: Oracle Linux 8 (64-bit) | S18: 28 | T18: 500 | U18: 16 | V18: ALTO | W18: PRODUCCIÓN | X18: NA | Y18: NA | AB18: SI | AC18: Veritas | AD18: Veritas-FUllMon-Ret15_UIO_00
J19: VIRTUAL | K19: tvc-srv-admapp - ELIMINADO | L19: Recursos Humanos Apicación | M19: 192.168.21.119 | Q19: Mauricio Rodriguez | R19: Microsoft Windows Server 2012 (64-bit) | S19: 8 | T19: 500 | U19: 4 | V19: MEDIO | W19: ELIMINADO | X19: SQL SERVER | Y19: SQL Server 2014 | AB19: NO equipo apagado
J20: VIRTUAL | K20: tvc-srv-admbd - ELIMINADO | L20: Recursos Humanos Base de Datos | M20: 192.168.21.121 | Q20: Mauricio Rodriguez | R20: Microsoft Windows Server 2012 (64-bit) | S20: 8 | T20: 500 | U20: 4 | V20: MEDIO | W20: ELIMINADO | X20: SQL SERVER | Y20: SQL Server 2014 | AB20: NO equipo apagado
J21: VIRTUAL | K21: tvc-srv-adprint | L21: Administrador de impresoras UIO | M21: 192.168.21.17 | O21: SI | P21: - | Q21: Hector Miranda/Graciela Ortiz | R21: Microsoft Windows Server 2016 (64-bit) | S21: 16 | T21: 350 | U21: 4 | V21: MEDIO | W21: PRODUCCIÓN | X21: NA | Y21: NA | AB21: SI | AC21: Veritas | AD21: Veritas-FUllWed-Ret15_UIO_08
J22: VIRTUAL | K22: tvc-srv-aduio2 | L22: Conector del AD | M22: 192.168.21.26 | N22: 200.63.213.27 | O22: SI | P22: - | Q22: Evelyn Puetate /Yurema Tobar | R22: Microsoft Windows Server 2016 (64-bit) | S22: 20 | T22: 150 | U22: 4 | V22: ALTO | W22: PRODUCCIÓN | X22: NA | Y22: NA | AB22: SI | AC22: Veritas | AD22: Veritas-FUllWed-Ret15_UIO_08
J23: VIRTUAL | K23: tvc-srv-aduio3 | L23: Active Directory secundario | M23: 192.168.21.27 | O23: SI | P23: - | Q23: Evelyn Puetate /Yurema Tobar | R23: Microsoft Windows Server 2016 (64-bit) | S23: 20 | T23: 150 | U23: 4 | V23: ALTO | W23: PRODUCCIÓN | AB23: SI | AC23: Veritas | AD23: Veritas-FUllWed-Ret15_UIO_08
J24: VIRTUAL | K24: tvc-srv-agdi | L24: Pagina Web Agencia Digital, tmbn tiene xtrim.tv, xtrim.com.ec, Pagina de Ingreso de contrato para vendedores, proveedores y distribuidores - mixtrim.com.ec/IngresoContratos | M24: 192.168.21.243 | N24: 200.63.213.43 | O24: SI | P24: - | Q24: Hector Miranda /Administrador de aplicaciones | R24: Red Hat Enterprise Linux 7 (64-bit) | S24: 48 | T24: 180 | U24: 8 | V24: ALTO | W24: PRODUCCIÓN | X24: MySQL | Y24: 5.6.28 Community Edition 64 bits | AB24: SI | AC24: Veritas | AD24: Veritas-FUllMon-Ret15_UIO_02
J25: VIRTUAL | K25: tvc-srv-amas | L25: Servidor de amas - Relacionado con las llamadas telefonicas. | M25: 192.168.21.31 | O25: SI | P25: - | Q25: Hector Miranda /Administrador de aplicaciones | R25: Windows 10 | S25: 8 | T25: 931.65 | U25: 4 | V25: BAJO | W25: PRODUCCIÓN | AB25: SI | AC25: Veritas | AD25: Veritas-FUllMon-Ret15_UIO_02
J26: VIRTUAL | K26: tvc-srv-apjaira | L26: Mesa de Servicios - Flujos internos. (con el tiempo se dará de baja) | M26: 192.168.21.35 | O26: SI | P26: - | Q26: Hector Miranda /Administrador de aplicaciones | R26: Microsoft Windows Server 2016 (64-bit) | S26: 20 | T26: 400 | U26: 4 | V26: BAJO | W26: PRODUCCIÓN | X26: NA | Y26: NA | AB26: SI | AC26: Veritas | AD26: Veritas-FUllThu-Ret15_UIO_09
J27: VIRTUAL | K27: tvc-srv-appadm | L27: Aplicaciones del sistema de nomina - Datalife | M27: 192.168.21.101 | O27: - | P27: SI | Q27: Jaqueline Andrade/Carlos Ayala/Christian Castillo | R27: Microsoft Windows Server 2022 (64-bit) | S27: 16 | T27: 160 | U27: 2 | V27: ALTO | W27: PRODUCCIÓN | AB27: SI | AC27: Veritas | AD27: Veritas-FUllWed-Ret15_UIO_06
J28: VIRTUAL | K28: tvc-srv-as2back | L28: SERVIDOR DE RESPALDO DEL AS2, DE LA INFOPRMACIÓN QUE ESTA EN EL ONEDRIVE. (3ER RESPALDO) | M28: 192.168.21.15 | O28: - | P28: SI | Q28: Jose Fernandez/Ivone Intriago | R28: Microsoft Windows Server 2022 (64-bit) | S28: 4 | T28: 300 | U28: 4 | V28: ALTO | W28: PRODUCCIÓN | AB28: SI | AC28: Veritas | AD28: Veritas-FUllMon-Ret15_UIO_00 Veritas-FullFri-Ret15_UIO_14
J29: VIRTUAL | K29: tvc-srv-autosrv | L29: Servidor autoservicios | M29: 192.168.21.16 | O29: - | P29: SI | Q29: Hector Miranda /Administrador de aplicaciones | R29: Ubuntu 22,04 LTS Linux (64-bit) | S29: 8 | T29: 100 | U29: 4 | V29: ALTO | W29: PRODUCCIÓN | X29: NA | Y29: NA | AB29: SI | AC29: Veritas | AD29: Veritas-FUllTue-Ret15_UIO_05
J30: VIRTUAL | K30: tvc-srv-bdadm | L30: Base de datos de sistema de nomina | M30: 192.168.21.102 | O30: - | P30: SI | Q30: Jaqueline Andrade/Carlos Ayala/Christian Castillo | R30: Microsoft Windows Server 2022 (64-bit) | S30: 16 | T30: 500 | U30: 4 | V30: ALTO | W30: PRODUCCIÓN | AB30: SI | AC30: veritas | AD30: Veritas-FUllWed-Ret15_UIO_06
J31: VIRTUAL | K31: tvc-srv-cluster3 | L31: Cluster base de datos | M31: 192.168.21.25 | O31: - | P31: SI | Q31: Carlos Ayala / Christian Castillo | R31: Red Hat Enterprise Linux 9 (64-bit) | S31: 4 | T31: 400 | U31: 2 | V31: ALTO | W31: PRODUCCIÓN | X31: NA | Y31: NA | AB31: SI | AC31: Veritas | AD31: Veritas-FUllTue-Ret15_UIO_05
J32: VIRTUAL | K32: tvc-srv-colecsoc | L32: Logs del SOC | M32: 192.168.21.236 | O32: - | P32: SI | Q32: Jose Fernandez/Alejandro Alvarez | R32: Red Hat Enterprise Linux 9.2 (64-bit) | S32: 8 | T32: 250 | U32: 4 | V32: ALTO | W32: PRODUCCIÓN | AB32: SI | AC32: Veritas | AD32: Veritas-FUllMon-Ret15_UIO_01
J33: VIRTUAL | K33: tvc-srv-condell | L33: Servidor Thincliente Dell | M33: 192.168.21.5 | O33: - | P33: SI | Q33: Evelyn Puetate/Yurema Tobar | R33: Microsoft Windows Server 2019 (64-bit) | S33: 8 | T33: 100 | U33: 4 | V33: ALTO | W33: PRODUCCIÓN | X33: NA | Y33: NA | AB33: SI | AC33: Veritas
J34: VIRTUAL | K34: tvc-srv-dbas2bi | L34: Enviar informacion de base de datos AS2 | M34: 192.168.21.13 | N34: 200.63.213.82 | O34: - | P34: SI | Q34: Carlos Ayala/Christian Castillo | R34: Red Hat Enterprise Linux 9 (64-bit) | S34: 8 | T34: 300 | U34: 8 | V34: ALTO | W34: PRODUCCIÓN
J35: VIRTUAL | K35: tvc-srv-dbjaira | L35: Servidor base de datos Jira | M35: 192.168.21.36 | O35: SI | P35: - | Q35: Carlos Ayala/Christian Castillo | R35: Microsoft Windows Server 2012 (64-bit) | S35: 8 | T35: 550 | U35: 2 | V35: MEDIO | W35: PRODUCCIÓN | X35: SQL SERVER | Y35: SQL Server 2012 | AB35: SI | AC35: Veritas | AD35: Veritas-FUllThu-Ret15_UIO_09
J36: VIRTUAL | K36: tvc-srv-desa-www | L36: Servidor www FSM | M36: 192.168.21.197 | O36: SI | P36: - | Q36: Hector Miranda/Administrador de aplicaciones | R36: Red Hat Enterprise Linux 6 (64-bit) | S36: 38 | T36: 100 | U36: 10 | V36: ALTO | W36: DESARROLLO
J37: VIRTUAL | K37: tvc-srv-dhcpuio | L37: Servidor DHCP y consola de Unifi (Wifi) | M37: 192.168.21.2 | O37: SI | P37: - | Q37: Luis Conteron/Guillermo Jurado | R37: Microsoft Windows Server 2016 (64-bit) | S37: 8 | T37: 80 | U37: 4 | V37: ALTO | W37: PRODUCCIÓN | X37: NA | Y37: NA | AB37: SI | AC37: Veritas | AD37: Veritas-FUllWed-Ret15_UIO_08
J38: VIRTUAL | K38: tvc-srv-eleuio - ELIMINADO | L38: Servidor elearning TEC. overtime | M38: 192.168.21.242 | N38: 200.63.213.25 | Q38: Julio Enriquez | R38: Microsoft Windows Server 2016 (64-bit) | S38: 3 | T38: 250 | U38: 3 | V38: BAJO | W38: ELIMINADO | X38: NA | Y38: NA | AB38: NO equipo apagado
J39: VIRTUAL | K39: tvc-srv-exuio | L39: Servidor de Correo | M39: 192.168.21.50 192.168.21.196 | N39: 200.63.213.13 | O39: - | P39: SI | Q39: Evelyn Puetate/Yurema Tobar | R39: Microsoft Windows Server 2022 (64-bit) | S39: 20 | T39: =250+150 -> 400 | U39: 4 | V39: ALTO | W39: PRODUCCIÓN | X39: NA | Y39: NA | AB39: SI | AC39: Veritas | AD39: Veritas-FUllWed-Ret15_UIO_06
J40: VIRTUAL | K40: tvc-srv-finform | L40: Servidor de Formas Hiperk - Reemplazado por el AS2 | M40: 192.168.21.46 | O40: SI | P40: - | Q40: Hector Miranda/Administrador de aplicaciones | R40: Microsoft Windows Server 2016 (64-bit) | S40: 6 | T40: 250 | U40: 4 | V40: BAJO | W40: PREPRODUCCIÓN | X40: NA | Y40: NA | AB40: SI | AC40: Veritas | AD40: Veritas-FUllWed-Ret15_UIO_06
J41: VIRTUAL | K41: tvc-srv-fsm | L41: Base Datos FSM | M41: 192.168.21.124 | O41: SI | P41: - | Q41: Carlos Ayala/Christian Castillo | R41: Red Hat Enterprise Linux 6.4 (64-bit) | S41: 64 | T41: 3000 | U41: 8 | V41: ALTO | W41: PRODUCCIÓN | X41: ORACLE | Y41: Oracle 11g R2 | AB41: Se respalda Base de Datos | AC41: Veritas | AD41: Veritas-FUllTue-Ret15_UIO_04
J42: VIRTUAL | K42: tvc-srv-ftp | L42: FTP Recargas efectos de consiliaciones | M42: 192.168.21.157 | N42: 200.63.213.64 | O42: SI | P42: - | Q42: Hector Miranda/Administrador de aplicaciones | R42: Red Hat Enterprise Linux 6 (64-bit) | S42: 2 | T42: 60 | U42: 1 | V42: ALTO | W42: PRODUCCIÓN | X42: NA | Y42: NA | AB42: SI | AC42: Veritas | AD42: Veritas-FUllTue-Ret15_UIO_03
J43: VIRTUAL | K43: tvc-srv-ftpac | L43: Ftp actualizaciones BackOffice | M43: 192.168.21.203 | N43: 200.63.213.68 | O43: SI | P43: - | Q43: pendiente de confirmacion David Villamar | R43: Red Hat Enterprise Linux 6 (64-bit) | S43: 4 | T43: 50 | U43: 2 | V43: MEDIO | W43: PRODUCCIÓN | X43: NA | Y43: NA | AB43: SI | AC43: veeam | AD43: Veritas-FullFri-Ret15_UIO_12
J44: VIRTUAL | K44: tvc-srv-gruptvc | L44: Pruebas pagina Grupo TVCable | M44: 192.168.21.123 | O44: SI | P44: - | Q44: Carlos Ayala / David Villamar | R44: Red Hat Enterprise Linux 7 (64-bit) | S44: 4 | T44: 120 | U44: 2 | V44: BAJO | W44: PREPRODUCCIÓN | X44: MySQL | Y44: 5.6.28 Community Edition 64 bits | AB44: SI | AC44: Veritas | AD44: Veritas-FUllMon-Ret15_UIO_01
...

Sheet GYE 2025
E2: INVENTARIO DE SERVIDORES VIRTUALIZADOS Y FISICOS GYE 2025
A5: Fecha de actualización: 25/09/2025 | H5: Actualizado por: | I5: Mireya Iturralde
B6: ENCLOSURE | C6: SRV FISICOS | D6: SERIE | E6: IP del blade | F6: TOTAL SRV FISICOS | G6: CARACTERISTICAS | H6: SOPORTE | I6: # SRV VIRTUALES | J6: TIPO DE SERVIDOR | K6: SRV VIRTUALES | L6: APLICACIÓN | M6: IP INTERNA | N6: IP PUBLICA | O6: PROTECCIÓN DE TREND MCRO XDR - SRV | P6: CORTEX | Q6: Persona responsable del uso del SRV | R6: PANDORA | S6: SISTEMA OPERATIVO | T6: MEMORIA | U6: Espacio Disco | V6: Procesador | W6: SISTEMAS CRITICOS | X6: NIVEL DE BACKUP | Y6: SERVIDOR PRODUCCIÓN / PREPRODUCCIÓN | Z6: BASE DE DATOS | AA6: VERSIÓN DB | AB6: COSTO SOPORTE | AC6: EMPRESA QUE DA SOPORTE | AD6: BACKUP SE REALIZA | AE6: PLATAFORMA DE BACKUP | AF6: POLITICA DE BACKUP | AG6: COMENTARIO
A7: GYE - C7000 | B7: C7000 - VDI | C7: BL460C | D7: CZ3741XKMH | E7: 192.168.9.50 | F7: 2 | G7: 2X Gen9, Intel(R) Xeon(R) CPU E5-2620 v4 @ 2.10GHz, 2 slot de c/u 128GB en total 256 GB RAM | H7: TERMINA 2023 | I7: =COUNTIF(J7:J8,"=VIRTUAL") -> 0 | AG7: -
C8: BL460C | D8: CZ3741XKN1 | E8: 192.168.9.49 | G8: 2X Gen9, Intel(R) Xeon(R) CPU E5-2620 v4 @ 2.10GHz, 2 slot de c/u de 128 GB en total 256 GB RAM | H8: TERMINA 2023 | AG8: No se ejecuta porque, es un srv replicado del cloud1
C9: BL460C | D9: CZ3741XKMF | E9: 192.168.9.51 | G9: 2X Gen9, Intel(R) Xeon(R) CPU E5-2620 v4 @ 2.10GHz, 2 slot de c/u 128GB en total 256 GB RAM | H9: TERMINA 2023 | J9: VIRTUAL | K9: TVC-SRV-N8NDES | L9: Pruebas con un software de gestión documental | M9: 192.168.77.21 | O9: - | P9: SI | Q9: Mauricio Rodriguez | R9: SI | S9: Red Hat Enterprise Linux 9.5 (64-bit) | T9: 8 | U9: 70 | V9: 2 | X9: BAJO | Y9: PREPRODUCCIÓN | Z9: NA | AA9: NA | AD9: SI | AE9: veritas | AF9: Veritas-FullWed-Ret90_GYE_18
C10: BL460C | E10: 192.168.9.53 | F10: 2 | G10: 2X Gen9, Intel(R) Xeon(R) CPU E5-2620 v4 @ 2.10GHz, 2 slot de c/u 128GB en total 256 GB RAM | H10: TERMINA 2023 | J10: VIRTUAL | K10: TVC-SRV-GYELZBXDB01 | L10: Proyecto Zabbix | M10: 192.168.77.22 | O10: - | P10: SI | Q10: Jose Fernandez/ Alejandro Alvarez | R10: SI | S10: Red Hat Enterprise Linux 9.5 (64-bit) | T10: 8 | U10: 100 | V10: 4 | X10: BAJO | Y10: PREPRODUCCIÓN | Z10: NA | AA10: NA | AD10: SI | AE10: veritas | AF10: Veritas-FullWed-Ret90_GYE_18
J11: VIRTUAL | K11: TVC-SRV-GYELZBXSRV01 | L11: Proyecto Zabbix | M11: 192.168.77.23 | O11: - | P11: SI | Q11: Jose Fernandez/ Alejandro Alvarez | R11: si | S11: Red Hat Enterprise Linux 9.5 (64-bit) | T11: 8 | U11: 100 | X11: BAJO | Y11: PREPRODUCCIÓN | Z11: NA | AA11: NA | AD11: SI | AE11: veritas | AF11: Veritas-FullWed-Ret90_GYE_18
J12: VIRTUAL | K12: XTR-SRV-WORKERNODTES | L12: CLUSTER KUBERNETS WORKER NODE PARA EL NUEVO BSS AMBIENTE DE TEST | M12: 192.168.76.24 | O12: - | P12: SI | Q12: Harry Salvatierra | R12: SI | S12: Red Hat Enterprise Linux 9.5 (64-bit) | T12: 16 | U12: 100 | V12: 8 | X12: MEDIO | Y12: TEST | AD12: SI | AE12: veritas | AF12: Veritas-Full-TueRet90_GYE_19
J13: VIRTUAL | K13: XTR-SRV-MASTERNODTES | L13: CLUSTER KUBERNETS MASTER NODE PARA EL NUEVO BSS AMBIENTE DE TEST | M13: 192.168.76.25 | O13: - | P13: SI | Q13: Harry Salvatierra | R13: SI | S13: Red Hat Enterprise Linux 9.5 (64-bit) | T13: 8 | U13: 50 | V13: 4 | X13: MEDIO | Y13: TEST | AD13: SI | AE13: veritas | AF13: Veritas-Full-TueRet90_GYE_19
J14: VIRTUAL | K14: XTR-SRV-WORKERNODDES | L14: CLUSTER KUBERNETS WORKER NODE PARA EL NUEVO BSS AMBIENTE DESARROLLO | M14: 192.168.77.11 | S14: Red Hat Enterprise Linux 9.5 (64-bit) | T14: 16 | U14: 100 | V14: 8 | X14: MEDIO | Y14: PREPRODUCCIÓN | AE14: veritas | AF14: Veritas-Full-MonRet90_GYE_20
J15: VIRTUAL | K15: XTR-SRV-MASTERNODDES | L15: CLUSTER KUBERNETS MASTER NODE PARA EL NUEVO BSS AMBIENTE DESARROLLO | M15: 192.168.77.10 | S15: Red Hat Enterprise Linux 9.5 (64-bit) | T15: 8 | U15: 50 | V15: 4 | X15: MEDIO | Y15: PREPRODUCCIÓN | AE15: veritas | AF15: Veritas-Full-MonRet90_GYE_20
J16: VIRTUAL | K16: TVC-SRV-LANDINGPAGE | L16: Boton de pagos-SRV ligado a landingpagebak y pro | M16: 192.168.76.21 | O16: - | P16: SI | Q16: David Villamar | R16: SI | S16: Ubuntu 22.04 LTS | T16: 4 | U16: 100 | V16: 4 | X16: ALTO | Y16: PREPRODUCCIÓN | AD16: SI | AE16: veritas | AF16: Veritas-Full-TueRet90_GYE_19
J17: VIRTUAL | K17: TVC-SRV-MEDIADORDACCclon | M17: 192.168.77.27
J18: VIRTUAL | K18: tvc-srv-njbdps2clon | M18: 192.168.77.28
J19: VIRTUAL | K19: XTR-SRV-BACKEND-VT | L19: Es usado para la celula de ventas, que lo configura Daniel Solano. Conexión con bitbucket.TEST | M19: 192.168.76.29 | O19: - | P19: SI | R19: SI | S19: Red Hat Enterprise Linux 9.5 (64-bit) | T19: 16 | U19: 250 | V19: 4 | W19: ALTO | X19: ALTO | Y19: TEST | AD19: SI | AE19: veritas | AF19: Veritas-FullSun-Ret90_GYE_14
J20: VIRTUAL | K20: XTR-SRV-PLAYOPSTES | M20: 192.168.76.15 | R20: SI | S20: Ubuntu 22.04 LTS
J21: VIRTUAL | K21: XTR-SRV-BACKEND-VTA | L21: Es usado para la celula de ventas, que lo configura Daniel Solano. Conexión con bitbucket.DESA | M21: 192.168.77.31 | P21: SI | Q21: Harry Salvatierra | R21: SI | S21: Red Hat Enterprise Linux 9.5 (64-bit) | T21: 16 | U21: 250 | V21: 4 | X21: MEDIO | Y21: PREPRODUCCIÓN | AD21: SI | AE21: veritas | AF21: Veritas-Full-TueRet90_GYE_19
J22: VIRTUAL | K22: XTR-SRV-DBRRHH | L22: BASE DE DATOS para el CMS (Sistema de gestión de contenido) del proyecto Intranet Xtrim. | M22: 192.168.77.32 | O22: SI | P22: - | R22: SI | S22: Red Hat Enterprise Linux 9.5 (64-bit) | T22: 4 | U22: 80 | V22: 4 | X22: BAJO | Y22: PREPRODUCCIÓN | AD22: SI | AE22: veritas | AF22: Veritas-FullWed-Ret90_GYE_18
J23: VIRTUAL | K23: XTR-SRV-DBINTRAXTR | L23: SERVIDOR DE BASES DE DATOS PARA EL PROYECTO DE RRHH - INTRANET (AMBIENTE DE TEST) | M23: 192.168.76.50 | Q23: Miguel Briones / Carlos Ayala | R23: SI | S23: Red Hat Enterprise Linux 9.5 (64-bit) | T23: 16 | U23: 100 | V23: 8 | X23: ALTO | Y23: TEST | Z23: SI | AD23: SI | AE23: veritas | AF23: Veritas-FullThu-Ret90_GYE_17
J24: VIRTUAL | K24: XTR-SRV-xtrimdesa-ad | L24: SERVIDOR DE DNS PARA EL AMBIENTE DE DESARROLLO Y TEST | M24: 192.168.77.35 | N24: APAGADO | O24: SI | Q24: Mireya Iturralde | R24: SI | S24: WINdows Server 2016 | T24: 12 | U24: 200 | V24: 6 | W24: ALTO | X24: ALTO | Y24: PREPRODUCCIÓN
J25: VIRTUAL | K25: XTR-SRV-FRONTEND-VT | L25: celula de ventas | M25: 192.168.76.30 | O25: - | P25: SI | R25: SI | S25: Red Hat Enterprise Linux 9.5 (64-bit) | T25: 16 | U25: 250 | V25: 4 | W25: ALTO | X25: ALTO | Y25: TEST | AD25: SI | AE25: veritas | AF25: Veritas-FullSun-Ret90_GYE_14
J26: VIRTUAL | K26: XTR-SRV-FRONTEND-VT | L26: Es usado para la celula de ventas, que lo configura Daniel Solano. Conexión con bitbucket.TEST | M26: 192.168.76.30 | S26: Red Hat Enterprise Linux 9.5 (64-bit) | T26: 16 | U26: 250 | V26: 4 | X26: MEDIO | Y26: TEST | AD26: SI | AE26: veritas | AF26: Veritas-FullSun-Ret90_GYE_14
J27: VIRTUAL | K27: XTR-SRV-FRONTEND-VTA | L27: Es usado para la celula de ventas, que lo configura Daniel Solano. Conexión con bitbucket.DESA | M27: 192.168.77.30 | P27: SI | Q27: Harry Salvatierra | R27: SI | S27: Red Hat Enterprise Linux 9.5 (64-bit) | T27: 16 | U27: 250 | V27: 4 | X27: MEDIO | Y27: PREPRODUCCIÓN | AD27: SI | AE27: veritas | AF27: Veritas-Full-TueRet90_GYE_19
J28: VIRTUAL | K28: XTR-SRV-GYELDASH01 | L28: GRAFANA(herramienta de visualización de datos y monitoreo de código abierto) | M28: 192.168.77.24 | O28: - | P28: SI | Q28: Jose Fernandez/ Alejandro Alvarez | R28: SI | S28: Red Hat Enterprise Linux 9.5 (64-bit) | T28: 8 | U28: 100 | V28: 4 | X28: BAJO | Y28: PREPRODUCCIÓN | AD28: SI | AE28: veritas | AF28: Veritas-FullWed-Ret90_GYE_18
J29: VIRTUAL | K29: XTR-SRV-GYELIPAM01 | L29: IPAM(herramientas utilizadas para gestionar y organizar las direcciones IP) | M29: 192.168.77.25 | O29: - | P29: SI | Q29: Jose Fernandez/ Alejandro Alvarez | R29: SI | S29: Ubuntu 22.04 LTS | T29: 8 | U29: 100 | V29: 4 | X29: BAJO | Y29: PREPRODUCCIÓN | AD29: SI | AE29: veritas | AF29: Veritas-FullWed-Ret90_GYE_18
J30: VIRTUAL | K30: XTR-SRV-LANDZAPPING | L30: Boton de pagosZAPPING -SRV ligado a landzappingbak y pro | M30: 192.168.76.28 | P30: SI | Q30: David Villamar | R30: SI | S30: Ubuntu 22.04 LTS | T30: 4 | U30: 100 | V30: 4 | X30: ALTO | Y30: TEST | AD30: SI | AE30: veritas | AF30: Veritas-Full-TueRet90_GYE_19
J31: VIRTUAL | K31: XTR-SRV-MASTERNODDES | M31: 192.168.77.10 | Q31: Harry Salvatierra | R31: SI | S31: Red Hat Enterprise Linux 9.5 (64-bit) | T31: 16 | U31: 100 | V31: 8 | X31: MEDIO | Y31: DES | AE31: veritas | AF31: Veritas-Full-MonRet90_GYE_20
J32: VIRTUAL | K32: XTR-SRV-WORKERNODDES | M32: 192.168.77.11 | Q32: Harry Salvatierra | R32: SI | S32: Red Hat Enterprise Linux 9.5 (64-bit) | T32: 16 | U32: 50 | V32: 8 | X32: MEDIO | Y32: DES | AE32: veritas | AF32: Veritas-Full-MonRet90_GYE_20
J33: VIRTUAL | K33: XTR-SRV-N8NTEST | L33: para la aplicación de automatización N8N | M33: 192.168.76.31 | O33: SI | Q33: Mauricio Rodriguez | R33: SI | S33: Red Hat Enterprise Linux 9.5 (64-bit) | T33: 8 | U33: 70 | V33: 8 | X33: BAJO | Y33: TEST | AD33: SI | AE33: veritas | AF33: Veritas-FullThu-Ret90_GYE_17
J34: VIRTUAL | K34: xtr-srv-njdpstest | L34: Servidor replica del 21,189 como test | M34: 192.168.76.42 | O34: SI | Q34: Harry Salvatierra | R34: SI | S34: CENTOS 7 | T34: 8 | U34: 240 | V34: 4 | X34: BAJO | Y34: TEST | AD34: SI | AE34: veritas | AF34: Veritas-Full-TueRet90_GYE_19
J35: VIRTUAL | K35: XTR-SRV-PORTALOPE | L35: servidor para Portal de Operaciones | M35: 192.168.77.34 | O35: SI | R35: SI | S35: REd Hat Enterprise Linux 9.5 (64-bit) | T35: 8 | U35: 150 | V35: 2 | X35: BAJO | Y35: PREPRODUCCIÓN | AD35: SI | AE35: veritas | AF35: Veritas-FullThu-Ret90_GYE_17
J36: VIRTUAL | K36: XTR-SRV-SGSI01 | L36: Herramienta CISO Assistant para llevar el control del SGSI en Ciberseguridad. | M36: 192.168.77.36 | O36: SI | Q36: Jose Fernandez/ Alejandro Alvarez | R36: SI | S36: REd Hat Enterprise Linux 9.5 (64-bit) | T36: 16 | U36: 100 | V36: 4 | X36: BAJO | Y36: PREPRODUCCIÓN | AD36: SI | AE36: veritas | AF36: Veritas-FullThu-Ret90_GYE_17
J37: VIRTUAL | K37: TVCSRVVCG | L37: VCENTER DE GUAYAQUIL | M37: 192.168.59.130 | O37: NO | P37: NO | R37: SI | S37: VMWARE PHOTO OS | T37: 19 | U37: 720 | V37: 4 | X37: ALTO | Y37: PRODUCCIÓN | AD37: SI | AE37: veritas | AF37: Veritas-FullThu-Ret90_GYE_15
C38: NO MOVER | J38: VIRTUAL | K38: TVC-SRV-ARBITER | L38: Servidor Arbitrario para el simplivity, permite la comunicación con los nodos GYE. Se puede reiniciar el servidor pero siempre debe estar arriba, porque si existe un problema con los nodos del Simplivity, luego no habria quien gestione quien es el nodo master. | M38: 192.168.59.54 | O38: - | P38: SI | Q38: Mireya Iturralde | R38: SI | S38: Windows Server 2019 | T38: 4 | U38: 50 | V38: 2 | X38: ALTO | Y38: PRODUCCIÓN | Z38: NA | AA38: NA | AD38: SI | AE38: veritas | AF38: Veritas-FullThu-Ret90_GYE_17 | AG38: -
B39: C7000-TEC | C39: BL460C | D39: CZ3741XKMS | E39: 192.168.94.41 | F39: 1 | G39: 2X Gen9, Intel(R) Xeon(R) CPU E5-2620 v4 @ 2.10GHz, 2 slot de c/u de 128GB en total 256 GB RAM | H39: TERMINA 2023 | J39: FISICO
C40: BL460C | D40: CZ3741XKMY | E40: 192.168.94.42 | F40: 1 | G40: 2X Gen9, Intel(R) Xeon(R) CPU E5-2620 v4 @ 2.10GHz, 2 slot de c/u de 128GB en total 256 GB RAM | H40: TERMINA 2023 | J40: nmen
C41: BL460C | D41: CZ3741XKMD | E41: 192.168.94.43 | F41: 1 | G41: 2X Gen9, Intel(R) Xeon(R) CPU E5-2620 v4 @ 2.10GHz, 2 slot de c/u de 128GB en total 256 GB RAM | H41: TERMINA 2023 | J41: FISICO
B42: HP C7000 | C42: BL460C | E42: 192.168.9.49 | F42: 1 | G42: 2X Gen10, Intel(R) Xeon(R) Gold 5120 CPU @ 2.20GHz, 2 slot de memoria : de 128GB y 256GB, en total 384 GB RAM | H42: TERMINA 2023 | I42: - | J42: FISICO | M42: 192.168.9.49 | O42: SI | P42: - | T42: 384 | U42: 9728 | V42: 16 | X42: MEDIO | Y42: PRODUCCIÓN | Z42: ORACLE | AA42: Oracle 11g R2 | AD42: NO | AF42: Por tema de espacio no tenemos donde almacenar 9TB, y no hay espacio para instalar un plugin de veeam y respaldar el srv oracle. | AG42: Por tema de espacio no tenemos donde almacenar 9TB, y no hay espacio para instalar un plugin de veeam y respaldar el srv oracle.
B43: HP C7000 - DBFLASH | C43: BL460C | D43: 2M293800B9 | E43: 192.168.59.12 | F43: 1 | G43: 2X Gen10, Intel(R) Xeon(R) Gold 5120 CPU @ 2.20GHz, 2 slot de memoria : de 128GB y 256GB, en total 384 GB RAM | H43: TERMINA 2023 | I43: - | J43: FISICO | K43: TVC-SRV-DBFLASH | L43: BASE DE DATOS STAND BY DE FSM POR FLASH COPY | M43: 192.168.59.12 | O43: SI | P43: - | Q43: Carlos Ayala / Hector Miranda | R43: SI | S43: Oracle Linux 7.6 | T43: 384 | U43: 9728 | V43: 16 | X43: MEDIO | Y43: PRODUCCIÓN | Z43: ORACLE | AA43: Oracle 11g R2 | AD43: NO | AF43: Por tema de espacio no tenemos donde almacenar 9TB, y no hay espacio para instalar un plugin de veeam y respaldar el srv oracle. | AG43: Por tema de espacio no tenemos donde almacenar 9TB, y no hay espacio para instalar un plugin de veeam y respaldar el srv oracle.
...

Sheet GYE
A2: INVENTARIO DE SERVIDORES VIRTUALIZADOS Y FISICOS GYE 2024
A5: Fecha de actualización: 25Julio2024 | H5: Actualizado por: | I5: Mireya Iturralde
B6: ENCLOSURE | C6: SRV FISICOS | D6: SERIE | E6: IP del blade | F6: TOTAL SRV FISICOS | G6: CARACTERISTICAS | H6: SOPORTE | I6: # SRV VIRTUALES | J6: TIPO DE SERVIDOR | K6: SRV VIRTUALES | L6: APLICACIÓN | M6: IP INTERNA | N6: IP PUBLICA | O6: PROTECCIÓN DE TREND MCRO XDR - SRV | P6: CORTEX | Q6: Persona responsable del uso del SRV | R6: SISTEMA OPERATIVO | S6: MEMORIA | T6: Espacio Disco | U6: Procesador | V6: SISTEMAS CRITICOS | W6: NIVEL DE BACKUP | X6: SERVIDOR PRODUCCIÓN / PREPRODUCCIÓN | Y6: BASE DE DATOS | Z6: VERSIÓN DB | AA6: COSTO SOPORTE | AB6: EMPRESA QUE DA SOPORTE | AC6: BACKUP SE REALIZA | AD6: PLATAFORMA DE BACKUP | AE6: POLITICA DE BACKUP | AF6: COMENTARIO
A7: GYE | B7: HP C3000 | C7: BL460C | D7: - | E7: 192.168.0.121 | F7: 3 | G7: 2 X Gen7 64 GB RAM | H7: NO | X7: - | Y7: N/A | Z7: N/A
C8: BL460C | D8: - | E8: 192.168.0.122 | G8: 2 X Gen7 64 GB RAM | H8: NO
C9: BL460C | D9: - | E9: 192.168.0.123 | G9: 2 X Gen7 64 GB RAM | H9: NO
A10: GYE | B10: C7000-VDI | C10: BL460C | D10: CZ3741XKMH | E10: 140.27.120.50 | F10: 2 | G10: 2X Gen9, Intel(R) Xeon(R) CPU E5-2620 v4 @ 2.10GHz, 2 slot de c/u 128GB en total 256 GB RAM | H10: TERMINA 2023 | I10: =COUNTIF(J10:J23,"=VIRTUAL") -> 14 | J10: VIRTUAL | K10: TVC-SRV-CCLOUD1 | L10: Servidor Cloud Clonnect de Citrix Principal | M10: 192.168.59.226 | O10: - | P10: SI | Q10: Yurema Tobar / Mireya Iturralde | R10: Microsoft Windows Server 2022 | S10: 4 | T10: 100 | U10: 4 | W10: ALTO | X10: PRODUCCIÓN | Y10: NA | Z10: NA | AC10: SI | AD10: veritas | AE10: Veritas-FullSun-Ret90_GYE_16 | AF10: -
C11: BL460C | D11: CZ3741XKN1 | E11: 140.27.120.49 | G11: 2X Gen9, Intel(R) Xeon(R) CPU E5-2620 v4 @ 2.10GHz, 2 slot de c/u de 128 GB en total 256 GB RAM | H11: TERMINA 2023 | J11: VIRTUAL | K11: TVC-SRV-CCLOUD2 | L11: Servidor Cloud Clonnect de Citrix Secundario | M11: 192.168.59.225 | O11: - | P11: SI | Q11: Yurema Tobar / Mireya Iturralde | R11: Microsoft Windows Server 2022 | S11: 4 | T11: 100 | U11: 4 | W11: BAJO | X11: PRODUCCIÓN | Y11: NA | Z11: NA | AC11: SI | AD11: veritas | AE11: Veritas-FullSun-Ret90_GYE_16 | AF11: No se ejecuta porque, es un srv replicado del cloud1
J12: VIRTUAL | K12: TVC-SRV-CTXIM0 | L12: Imagen maestra para servidores web y win de citrix | M12: 192.168.59.221 | O12: - | P12: SI | Q12: Yurema Tobar / Mireya Iturralde | R12: Microsoft Windows Server 2022 | S12: 8 | T12: 230 | U12: 4 | W12: ALTO | X12: PRODUCCIÓN | Y12: NA | Z12: NA | AC12: SI | AD12: veritas | AE12: Veritas-FullSun-Ret90_GYE_16 | AF12: -
J13: VIRTUAL | K13: TVC-SRV-CTXWB01 | L13: Servidor web para citrix cloud. | M13: 192.168.17.11 | O13: - | P13: SI | Q13: Yurema Tobar / Mireya Iturralde | R13: Microsoft Windows Server 2022 | S13: 32 | T13: 230 | U13: 4 | W13: MEDIO | X13: PRODUCCIÓN | Y13: NA | Z13: NA | AC13: NO | AF13: SERVIDOR ES UN CLON DE LA IMAGEN MAESTRA
J14: VIRTUAL | K14: TVC-SRV-CTXWN01 | L14: Servidor de aplicaciones windows para citrix cloud. | M14: 192.168.17.16 | O14: - | P14: SI | Q14: Yurema Tobar / Mireya Iturralde | R14: Microsoft Windows Server 2022 | S14: 32 | T14: 230 | U14: 4 | W14: MEDIO | X14: PRODUCCIÓN | Y14: NA | Z14: NA | AC14: NO | AF14: SERVIDOR ES UN CLON DE LA IMAGEN MAESTRA
J15: VIRTUAL | K15: TVC-SRV-CTXWN02 | L15: Servidor de aplicaciones windows para citrix cloud. | M15: 192.168.17.12 | O15: - | P15: SI | Q15: Yurema Tobar / Mireya Iturralde | R15: Microsoft Windows Server 2022 | S15: 32 | T15: 230 | U15: 4 | W15: MEDIO | X15: PRODUCCIÓN | Y15: NA | Z15: NA | AC15: NO | AF15: SERVIDOR ES UN CLON DE LA IMAGEN MAESTRA
J16: VIRTUAL | K16: TVC-SRV-CTXWN03 | L16: Servidor de aplicaciones windows para citrix cloud. | M16: 192.168.17.13 | O16: - | P16: SI | Q16: Yurema Tobar / Mireya Iturralde | R16: Microsoft Windows Server 2022 | S16: 32 | T16: 230 | U16: 4 | W16: MEDIO | X16: PRODUCCIÓN | Y16: NA | Z16: NA | AC16: NO | AF16: SERVIDOR ES UN CLON DE LA IMAGEN MAESTRA
J17: VIRTUAL | K17: TVC-SRV-CTXWN04 | L17: Servidor de aplicaciones windows para citrix cloud. | M17: 192.168.17.14 | O17: - | P17: SI | Q17: Yurema Tobar / Mireya Iturralde | R17: Microsoft Windows Server 2022 | S17: 32 | T17: 230 | U17: 4 | W17: MEDIO | X17: PRODUCCIÓN | Y17: NA | Z17: NA | AC17: NO | AF17: SERVIDOR ES UN CLON DE LA IMAGEN MAESTRA
J18: VIRTUAL | K18: TVC-SRV-CTXWN06 | L18: Servidor de aplicaciones windows para citrix cloud. | M18: 192.168.17.10 | O18: - | P18: SI | Q18: Yurema Tobar / Mireya Iturralde | R18: Microsoft Windows Server 2022 | S18: 32 | T18: 230 | U18: 4 | W18: MEDIO | X18: PRODUCCIÓN | Y18: NA | Z18: NA | AC18: NO | AF18: SERVIDOR ES UN CLON DE LA IMAGEN MAESTRA
J19: VIRTUAL | K19: TVC-SRV-KMS1 | L19: Servidor de licencias RDS para Citrix. | M19: 192.168.59.230 | O19: - | P19: SI | Q19: Yurema Tobar / Mireya Iturralde | R19: Microsoft Windows Server 2022 | S19: 8 | T19: 100 | U19: 4 | W19: ALTO | X19: PRODUCCIÓN | Y19: NA | Z19: NA | AC19: SI | AD19: veritas | AE19: Veritas-FullSun-Ret90_GYE_16 | AF19: -
J20: VIRTUAL | K20: TVC-SRV-PROFILE | L20: Servidor de Perfiles Ambiente Citrix Cloud | M20: 192.168.17.5 | O20: - | P20: SI | Q20: Yurema Tobar / Mireya Iturralde | R20: Microsoft Windows Server 2022 | S20: 16 | T20: 600 | U20: 4 | W20: ALTO | X20: PRODUCCIÓN | Y20: NA | Z20: NA | AC20: SI | AD20: veritas | AE20: Veritas-FullSun-Ret90_GYE_16 | AF20: -
J21: VIRTUAL | K21: TVC-SRV-SFRONT1 | L21: Servidor de StoreFront Citrix Primary | M21: 192.168.59.227 | O21: - | P21: SI | Q21: Yurema Tobar / Mireya Iturralde | R21: Microsoft Windows Server 2022 | S21: 8 | T21: 100 | U21: 4 | W21: ALTO | X21: PRODUCCIÓN | Y21: NA | Z21: NA | AC21: SI | AD21: veritas | AE21: Veritas-FullSun-Ret90_GYE_16 | AF21: -
J22: VIRTUAL | K22: TVC-SRV-SFRONT2 | L22: Servidor de StoreFront Citrix Secundario | M22: 192.168.59.228 | O22: - | P22: SI | Q22: Yurema Tobar / Mireya Iturralde | R22: Microsoft Windows Server 2022 | S22: 8 | T22: 100 | U22: 4 | W22: BAJO | X22: PRODUCCIÓN | Y22: NA | Z22: NA | AC22: NO | AF22: No se ejecuta porque, es un srv replicado del storefront2
J23: VIRTUAL | K23: TVC-SRVG-CTXFS2 | L23: Servidor data usuarios | M23: 192.168.59.233 | O23: SI | P23: - | Q23: Yurema Tobar | R23: 90 | S23: 8 | T23: 1024 | U23: 6 | W23: ALTO | X23: PRODUCCIÓN | Y23: NA | Z23: NA | AC23: SI | AD23: veritas | AE23: Veritas-FullSun-Ret90_GYE_16
A24: GYE | B24: C7000-TI | C24: BL460C | D24: CZ3741XKMM | E24: 140.27.120.51 | F24: 1 | G24: 2X Gen9, Intel(R) Xeon(R) CPU E5-2620 v4 @ 2.10GHz, 2 slot de c/u 128GB en total 256 GB RAM | H24: TERMINA 2023 | I24: =COUNTIF(J24:J39,"=VIRTUAL") -> 16 | J24: VIRTUAL | K24: vREALIZE LCM APPLIANCE | L24: Se creo por default una vez instalado el vmware. | M24: 140.27.120.210 | O24: - | P24: - | Q24: Yurema Tobar / Guillermo Jurado | R24: Linux OTRO | S24: 6 | T24: 78 | U24: 4 | W24: DAR DE BAJA | X24: PRODUCCIÓN | Y24: NA | Z24: NA | AC24: SI | AD24: veritas | AF24: -
C25: BL460C | D25: CZ3741XKMF | E25: 140.27.120.52 | F25: 1 | G25: 2X Gen9, Intel(R) Xeon(R) CPU E5-2620 v4 @ 2.10GHz, 2 slot de c/u 128GB en total 256 GB RAM | H25: TERMINA 2023 | J25: VIRTUAL | K25: PC-REMOTE | L25: Equipo para escritorio remoto para Xavier León | M25: 192.168.17.6 | O25: - | P25: SI | Q25: Xavier León | R25: Windows 11 PRO | S25: 8 | T25: 200 | U25: 2 | W25: BAJO | X25: PREPRODUCCIÓN | AC25: no
C26: BL460C | D26: CZ3741XKN5 | E26: 140.27.120.53 | F26: 1 | G26: 2X Gen9, Intel(R) Xeon(R) CPU E5-2620 v4 @ 2.10GHz, 2 slot de c/u 128GB en total 256 GB RAM | H26: TERMINA 2023 | J26: VIRTUAL | K26: TVC-SRV-DOCKQA | L26: SERVIDOR DE DOCKERS DE DESARROLLO, PARA EL AMBIENTE DE CONTROL DE CALIDAD. clonado del 59.189 | M26: 192.168.59.140 | O26: - | P26: SI | Q26: Mauricio Rodriguez | R26: Ubuntu 20.04 LTS | S26: 32 | T26: 220 | U26: 4 | W26: BAJO | X26: PREPRODUCCIÓN | Y26: NA | Z26: NA | AD26: veeam
J27: VIRTUAL | K27: TVC-SRV-DWTEST | L27: Prueba de DatawareHouse | M27: 192.168.59.125 | O27: - | P27: SI | Q27: Carlos Ayala / Hector Miranda | R27: Ubuntu 22.04 | S27: 4 | T27: 120 | U27: 2 | W27: MEDIO | X27: PREPRODUCCIÓN | Y27: NA | Z27: NA | AC27: SI | AF27: -
J28: VIRTUAL | K28: TVC-SRV-FRONQA | L28: SERVIDOR FRONT END, PARA EL AMBIENTE DE CONTROL DE CALIDAD. | M28: 192.168.59.142 | O28: - | P28: SI | Q28: Mauricio Rodriguez | R28: Ubuntu 22.04 LTS | S28: 2 | T28: 30 | U28: 2 | W28: BAJO | X28: PREPRODUCCIÓN | Y28: NA | Z28: NA | AC28: SI | AD28: veeam | AF28: -
J29: VIRTUAL | K29: TVC-SRV-HAPROXYQA | L29: SERVIDOR DE HAPROXY, PARA EL AMBIENTE DE CONTROL DE CALIDAD. clonado 59.200 | M29: 192.168.59.141 | O29: - | P29: SI | Q29: Mauricio Rodriguez | R29: Ubuntu 22.04 LTS | S29: 8 | T29: 80 | U29: 4 | W29: BAJO | X29: PREPRODUCCIÓN | AC29: SI | AD29: veeam | AF29: -
J30: VIRTUAL | K30: TVC-SRV-HKTEST | L30: Servidor HIperK pruebas | M30: 140.27.120.109 | O30: SI | P30: - | Q30: Carlos Ayala | R30: Red Hat Enterprise Linux 6,9 | S30: 20 | T30: 350 | U30: 4 | W30: BAJO | X30: PREPRODUCCIÓN | Y30: NA | Z30: NA | AC30: SI | AF30: -
J31: VIRTUAL | K31: TVC-SRV-PREDBAPI | L31: Base de datos del Middleware Mysql Preproducción API. (Se confirma con Mauricio) | M31: 192.168.59.199 | O31: - | P31: SI | Q31: Carlos Ayala / Christian Castillo | R31: Ubuntu 22.04 LTS | S31: 8 | T31: 100 | U31: 4 | V31: BAJO | W31: MEDIO | X31: PREPRODUCCIÓN | Y31: MYSQL | Z31: MySQL 8 community edition | AC31: SI | AD31: veritas | AE31: Veritas-Fulltue-Ret90_GYE_01 | AF31: -
J32: VIRTUAL | K32: TVC-SRV-PREHAPROXY | L32: HA PROXY Y BASE DE DATOS. AMBIENTE DE PRE-PRODUCCION de Middleware (Se confirma con Mauricio) | M32: 192.168.59.201 | O32: - | P32: SI | Q32: Administrador de aplicaciones / Mauricio Rodriguez / Carlos Ayala / Christian Castillo | R32: Ubuntu 22.04 LTS | S32: 8 | T32: 80 | U32: 4 | V32: BAJO | W32: MEDIO | X32: PREPRODUCCIÓN | Y32: MYSQL | Z32: MySQL 8 community edition | AC32: SI | AD32: veritas | AE32: Veritas-Fulltue-Ret90_GYE_01 | AF32: -
J33: VIRTUAL | K33: TVC-SRV-PREWSO2API1 | L33: Servidor WSO2 Api Manager para el Middleware (Se confirma con Mauricio) | M33: 192.168.59.186 | O33: - | P33: SI | Q33: Administrador de aplicaciones / Mauricio Rodriguez | R33: Ubuntu 20.04 LTS | S33: 16 | T33: 75 | U33: 4 | V33: BAJO | W33: ALTO | X33: PREPRODUCCIÓN | Y33: NA | Z33: NA | AC33: SI | AD33: veritas | AE33: Veritas-Fulltue-Ret90_GYE_01 | AF33: -
J34: VIRTUAL | K34: TVC-SRV-PREWSO2IDEN | L34: Servidor WSO2 Identity para el Middleware (Se confirma con Mauricio) | M34: 192.168.59.187 | O34: - | P34: SI | Q34: Administrador de aplicaciones / Mauricio Rodriguez | R34: Ubuntu 20.04 LTS | S34: 16 | T34: 75 | U34: 4 | V34: BAJO | W34: ALTO | X34: PREPRODUCCIÓN | Y34: NA | Z34: NA | AC34: SI | AD34: veritas | AE34: Veritas-Fulltue-Ret90_GYE_01 | AF34: -
J35: VIRTUAL | K35: TVC-SRV-PREWSO2DB | L35: BD REDIS y para el Middleware (Se confirma con Mauricio) | M35: 192.168.59.188 | O35: - | P35: SI | Q35: Carlos Ayala / Christian Castillo | R35: Ubuntu 20.04 LTS | S35: 16 | T35: 90 | U35: 4 | V35: BAJO | W35: ALTO | X35: PREPRODUCCIÓN | Y35: NA | Z35: NA | AC35: SI | AD35: veritas | AE35: Veritas-Fulltue-Ret90_GYE_01 | AF35: -
J36: VIRTUAL | K36: TVC-SRV-PREWSO2NOD1 | L36: Servidor WSO2 Nodos microservicios para el Middleware - Preproducción (Se confirma con Mauricio) | M36: 192.168.59.189 | N36: 190.154.47.189 | O36: - | P36: SI | Q36: Administrador de aplicaciones / Mauricio Rodriguez | R36: Ubuntu 20.04 LTS | S36: 32 | T36: 220 | U36: 4 | V36: BAJO | W36: ALTO | X36: PREPRODUCCIÓN | Y36: NA | Z36: NA | AC36: SI | AD36: veritas | AE36: Veritas-FullThu-Ret90_GYE_15 | AF36: -
J37: VIRTUAL | K37: TVC-SRV-SSTEST | L37: Servidor SoftSwitch preproducción, y pruebas de conexiones a las entidades bancarias. | M37: 192.168.59.231 | N37: 190.154.47.232 | O37: - | P37: SI | Q37: Administrador de aplicaciones / Hector Miranda | R37: Microsoft Windows Server 2022 | S37: 16 | T37: 120 | U37: 4 | V37: BAJO | W37: BAJO | X37: PREPRODUCCIÓN | Y37: NA | Z37: NA | AC37: SI | AE37: Veritas-FullMon-SSTEST | AF37: -
J38: VIRTUAL | K38: TVC-SRV-WSO2DBQA | L38: BD REDIS para el Middleware y MongoDB Zapping, PARA AMBIENTE DE CONTROL DE CALIDAD. | M38: 192.168.59.143 | O38: - | P38: SI | Q38: Mauricio Rodriguez | R38: Ubuntu 20.04 LTS | S38: 32 | T38: 180 | U38: 8 | W38: BAJO | X38: PRODUCCIÓN | Y38: NA | Z38: NA | AC38: SI | AD38: veritas | AF38: -
C39: NO MOVER | J39: VIRTUAL | K39: TVC-SRV-ARBITER | L39: Servidor Arbitrario para el simplivity, permite la comunicación con los nodos GYE. Se puede reiniciar el servidor pero siempre debe estar arriba, porque si existe un problema con los nodos del Simplivity, luego no habria quien gestione quien es el nodo master. | M39: 192.168.59.54 | O39: - | P39: SI | Q39: Yurema Tobar/Mireya Iturralde | R39: Windows Server 2019 | S39: 4 | T39: 50 | U39: 2 | W39: ALTO | X39: PRODUCCIÓN | Y39: NA | Z39: NA | AC39: SI | AD39: veritas | AE39: Veritas-FullThu-Ret90_GYE_17 | AF39: -
B41: C7000-TEC | C41: BL460C | D41: CZ3741XKMS | E41: 192.168.94.41 | F41: 1 | G41: 2X Gen9, Intel(R) Xeon(R) CPU E5-2620 v4 @ 2.10GHz, 2 slot de c/u de 128GB en total 256 GB RAM | H41: TERMINA 2023 | I41: =COUNTIF(J41:J50,"=VIRTUAL") -> 10 | J41: VIRTUAL | K41: CoreViewGYE | L41: Funcionalidad: Gestion de plataforma ARRIS | M41: 192.168.87.60 | O41: - | P41: SI | Q41: Jose Lopez / William Chenche | R41: Microsoft Windows Server 2022 | S41: 16 | T41: 120 | U41: 4 | W41: ALTO | X41: PRODUCCIÓN | AD41: veeam
C42: BL460C | D42: CZ3741XKMY | E42: 192.168.94.42 | F42: 1 | G42: 2X Gen9, Intel(R) Xeon(R) CPU E5-2620 v4 @ 2.10GHz, 2 slot de c/u de 128GB en total 256 GB RAM | H42: TERMINA 2023 | J42: VIRTUAL | K42: DhcpGponGYE | L42: Funcionalidad: Servidor DHCP, para la plataforma GPON en R2 & R3. | M42: 192.168.1.200 | O42: - | P42: SI | Q42: Christian Francis | R42: Ubuntu 22.04 LTS | S42: 16 | T42: 170 | U42: 4 | W42: ALTO | X42: PRODUCCIÓN | AD42: veeam
C43: BL460C | D43: CZ3741XKMD | E43: 192.168.94.43 | F43: 1 | G43: 2X Gen9, Intel(R) Xeon(R) CPU E5-2620 v4 @ 2.10GHz, 2 slot de c/u de 128GB en total 256 GB RAM | H43: TERMINA 2023 | J43: VIRTUAL | K43: dnscorp2.satnet.net | L43: Funcionalidad: Servidor DNS decundario, clientes corporativos | M43: 192.168.1.72 | O43: - | P43: SI | Q43: Christian Francis | R43: Ubuntu 22.04 LTS | S43: 24 | T43: 120 | U43: 24 | W43: ALTO | X43: PRODUCCIÓN | Y43: NA | Z43: NA | AD43: veeam
J44: VIRTUAL | K44: dnsgpon2 | L44: Funcionalidad: Servidor DNS recursivo, clientes residenciales HFC, GPON | M44: 192.168.1.70 | O44: - | P44: SI | Q44: Christian Francis | R44: Ubuntu 22.04 LTS | S44: 24 | T44: 120 | U44: 24 | W44: ALTO | X44: PRODUCCIÓN | Y44: NA | Z44: NA | AD44: veeam
...

Sheet Licencia Red Hat
B3: DESCRIPCIÓN | E3: TIPO DE LICENCIA | F3: CANTIDAD | G3: CONTRATO | H3: CADUCA | L3: DESCRIPCIÓN | O3: TIPO DE LICENCIA | P3: CANTIDAD | Q3: CONTRATO | R3: CADUCA | S3: OBSERVACION
B4: LICENCIA PARA LOS 4 HOST DEL C7000 GYE | E4: DATACENTER | F4: 4 | L4: LICENCIA PARA LOS 3 HOST DEL C7000 GYE - TEC | O4: DATACENTER PREIMUN | P4: 3 | Q4: 17020451 | R4: 45744 | S4: NO RENOVAR, SE COMPRO EN MARZO 2024
B5: ProLiant DL380 Gen10 | C5: 192.168.9.28 | D5: NODO DEL SIMPLIVITY GYE | E5: UTIL PORQUE TENEMOS SRV VIRTUALES CON RED HAT | G5: 11025116 | H5: 45481 | L5: BL460C | M5: 192.168.94.37 | N5: BLADE DEL C7000
B6: ProLiant DL380 Gen10 | C6: 192..168.9.30 | D6: NODO DEL SIMPLIVITY GYE | G6: 11025116 | H6: 45481 | L6: BL460C | M6: 192.168.94.38 | N6: BLADE DEL C7000
B7: ProLiant DL380 Gen10 | C7: 192.168.9.32 | D7: NODO DEL SIMPLIVITY GYE | G7: 16832113 | H7: 45500 | L7: BL460C | M7: 192.168.94.39 | N7: BLADE DEL C7000
B8: ProLiant DL380 Gen10 | C8: 192.168.9.34 | D8: NODO DEL SIMPLIVITY GYE | G8: 16832113 | H8: 45500 | L8: LICENCIAS PARA HOSTS DEL C7000 - UIO TEC | O8: HOST AND VIRTUAL STANDARD | P8: 2 | Q8: 16810868 | R8: 45489 | S8: ACTUALIZAR LA FECHA POR PARTE DE CONECTA
B9: LICENCIA PARA LOS 2 NODOS DEL SIMPLIVITY UIO | E9: DATACENTER | F9: 4 | L9: BL460C | M9: tec-iway-db | N9: BLADE DEL C7000
B10: ProLiant DL380 | C10: 192.168.34.160 | D10: NODO DEL SIMPLIVITY UIO | E10: UTIL PORQUE TENEMOS SRV VIRTUALES CON RED HAT | G10: 16832113 | H10: 45500 | L10: BL460C | M10: tec-iway-db-backup | N10: BLADE DEL C7000
B11: ProLiant DL380 | C11: 192.168.34.162 | D11: NODO DEL SIMPLIVITY UIO | G11: 16832113 | H11: 45516
B12: ProLiant DL380 | C12: 192.168.34.164 | D12: NODO DEL SIMPLIVITY UIO | G12: 17020451 | H12: 45744 | T12: DATACENTER - 9 | V12: OBSERVACIÓN
B13: ProLiant DL380 | C13: 192.168.34.166 | D13: NODO DEL SIMPLIVITY UIO | G13: 17020451 | H13: 45744 | T13: SIMPLIVITY GYE | U13: 4
B14: STAND ALONE GYE | E14: HOST AND VIRTUAL | F14: 2 | L14: TOTAL DE LICENCIAS DATACENTER PREMIUM | P14: =P4 -> 3 | T14: SIMPLIVITY UIO | U14: 2 | V14: + 2 Renovadas en Marzo
B15: BL460C | C15: 192.168.59.10 | D15: BASE DE DATOS DEL FSM | E15: NO ES NECESARIO | G15: - | H15: - | T15: C7000 GYE - VMWARE | U15: 1
B16: SUN FIRE X4275 | C16: 140.27.120.165 | D16: TVC-INSIGHT1 | E16: APAGADO | G16: - | H16: - | L16: TOTAL DE LICENCIAS HOST AND VIRTUAL PREMIUM | P16: =P8 -> 2
B17: SUN FIRE X4275 | C17: 140.27.120.164 | D17: TVC-INSIGHT2 | E17: AUN UTILIZADA | F17: USADAS - consume 2 | G17: 14254849 | H17: 45498
B18: ODA X8-2HA UIO | E18: HOST AND VIRTUAL | F18: 8 | T18: VIRTUAL NODES - 7 | V18: OBSERVACIÓN
B19: ODA X8-2HA | C19: 192.168.21.120 | D19: DPS - 192.168.21.147 | E19: NO PERMITE SUSCRIBIRLA | T19: TVC-INSIGHT1 - GYE | U19: 1 | V19: APAGADO
B20: ODA X8-2HA | C20: 192.168.21.122 | D20: INSIGHT - 192.168.31.200 | N20: DATACENTER | O20: 9 | T20: TVC-INSIGHT2 - GYE | U20: 1
D21: JBOSS - 192.168.21.175 | N21: VIRTUAL NODES | O21: 7 | T21: C7000 GYE - DB FLASH COPY | U21: 1
D22: INSIGHT - 192.168.31.190 | T22: tvc-srv-dbfsm - Base Datos FSM | U22: 1
B23: LICENCIAS PARA HOSTS DEL C7000 - UIO | E23: DATACENTER | F23: 3 | T23: tvc-srv-dbfin - Base de datops Iperk | U23: 1
